Internal Server Error: /
Traceback (most recent call last):
  File "/Library/Frameworks/Python.framework/Versions/3.6/lib/python3.6/site-packages/django/core/handlers/exception.py", line 41, in inner
    response = get_response(request)
  File "/Library/Frameworks/Python.framework/Versions/3.6/lib/python3.6/site-packages/django/core/handlers/base.py", line 187, in _get_response
    response = self.process_exception_by_middleware(e, request)
  File "/Library/Frameworks/Python.framework/Versions/3.6/lib/python3.6/site-packages/django/core/handlers/base.py", line 185, in _get_response
    response = wrapped_callback(request, *callback_args, **callback_kwargs)
  File "/Users/chalfant/Desktop/site/COLOSite/requestApp/views.py", line 19, in home
    if form.is_valid():
  File "/Library/Frameworks/Python.framework/Versions/3.6/lib/python3.6/site-packages/django/forms/forms.py", line 183, in is_valid
    return self.is_bound and not self.errors
  File "/Library/Frameworks/Python.framework/Versions/3.6/lib/python3.6/site-packages/django/forms/forms.py", line 175, in errors
    self.full_clean()
  File "/Library/Frameworks/Python.framework/Versions/3.6/lib/python3.6/site-packages/django/forms/forms.py", line 385, in full_clean
    self._clean_form()
  File "/Library/Frameworks/Python.framework/Versions/3.6/lib/python3.6/site-packages/django/forms/forms.py", line 412, in _clean_form
    cleaned_data = self.clean()
  File "/Users/chalfant/Desktop/site/COLOSite/requestApp/forms.py", line 39, in clean
    man_email= self.cleaned_data['man_email']
KeyError: 'man_email'
Exception while resolving variable 'request' in template '500.html'.
Traceback (most recent call last):
  File "/Library/Frameworks/Python.framework/Versions/3.6/lib/python3.6/site-packages/django/core/handlers/exception.py", line 41, in inner
    response = get_response(request)
  File "/Library/Frameworks/Python.framework/Versions/3.6/lib/python3.6/site-packages/django/core/handlers/base.py", line 187, in _get_response
    response = self.process_exception_by_middleware(e, request)
  File "/Library/Frameworks/Python.framework/Versions/3.6/lib/python3.6/site-packages/django/core/handlers/base.py", line 185, in _get_response
    response = wrapped_callback(request, *callback_args, **callback_kwargs)
  File "/Users/chalfant/Desktop/site/COLOSite/requestApp/views.py", line 19, in home
    if form.is_valid():
  File "/Library/Frameworks/Python.framework/Versions/3.6/lib/python3.6/site-packages/django/forms/forms.py", line 183, in is_valid
    return self.is_bound and not self.errors
  File "/Library/Frameworks/Python.framework/Versions/3.6/lib/python3.6/site-packages/django/forms/forms.py", line 175, in errors
    self.full_clean()
  File "/Library/Frameworks/Python.framework/Versions/3.6/lib/python3.6/site-packages/django/forms/forms.py", line 385, in full_clean
    self._clean_form()
  File "/Library/Frameworks/Python.framework/Versions/3.6/lib/python3.6/site-packages/django/forms/forms.py", line 412, in _clean_form
    cleaned_data = self.clean()
  File "/Users/chalfant/Desktop/site/COLOSite/requestApp/forms.py", line 39, in clean
    man_email= self.cleaned_data['man_email']
KeyError: 'man_email'

During handling of the above exception, another exception occurred:

Traceback (most recent call last):
  File "/Library/Frameworks/Python.framework/Versions/3.6/lib/python3.6/site-packages/django/template/base.py", line 882, in _resolve_lookup
    current = current[bit]
  File "/Library/Frameworks/Python.framework/Versions/3.6/lib/python3.6/site-packages/django/template/context.py", line 87, in __getitem__
    raise KeyError(key)
KeyError: 'request'

During handling of the above exception, another exception occurred:

Traceback (most recent call last):
  File "/Library/Frameworks/Python.framework/Versions/3.6/lib/python3.6/site-packages/django/template/base.py", line 888, in _resolve_lookup
    if isinstance(current, BaseContext) and getattr(type(current), bit):
AttributeError: type object 'Context' has no attribute 'request'

During handling of the above exception, another exception occurred:

Traceback (most recent call last):
  File "/Library/Frameworks/Python.framework/Versions/3.6/lib/python3.6/site-packages/django/template/base.py", line 896, in _resolve_lookup
    current = current[int(bit)]
ValueError: invalid literal for int() with base 10: 'request'

During handling of the above exception, another exception occurred:

Traceback (most recent call last):
  File "/Library/Frameworks/Python.framework/Versions/3.6/lib/python3.6/site-packages/django/template/base.py", line 903, in _resolve_lookup
    (bit, current))  # missing attribute
django.template.base.VariableDoesNotExist: Failed lookup for key [request] in "[{'True': True, 'False': False, 'None': None}]"
"POST / HTTP/1.1" 500 746
Internal Server Error: /
Traceback (most recent call last):
  File "/Library/Frameworks/Python.framework/Versions/3.6/lib/python3.6/site-packages/django/core/handlers/exception.py", line 41, in inner
    response = get_response(request)
  File "/Library/Frameworks/Python.framework/Versions/3.6/lib/python3.6/site-packages/django/core/handlers/base.py", line 187, in _get_response
    response = self.process_exception_by_middleware(e, request)
  File "/Library/Frameworks/Python.framework/Versions/3.6/lib/python3.6/site-packages/django/core/handlers/base.py", line 185, in _get_response
    response = wrapped_callback(request, *callback_args, **callback_kwargs)
  File "/Users/chalfant/Desktop/site/COLOSite/requestApp/views.py", line 19, in home
    if form.is_valid():
  File "/Library/Frameworks/Python.framework/Versions/3.6/lib/python3.6/site-packages/django/forms/forms.py", line 183, in is_valid
    return self.is_bound and not self.errors
  File "/Library/Frameworks/Python.framework/Versions/3.6/lib/python3.6/site-packages/django/forms/forms.py", line 175, in errors
    self.full_clean()
  File "/Library/Frameworks/Python.framework/Versions/3.6/lib/python3.6/site-packages/django/forms/forms.py", line 385, in full_clean
    self._clean_form()
  File "/Library/Frameworks/Python.framework/Versions/3.6/lib/python3.6/site-packages/django/forms/forms.py", line 412, in _clean_form
    cleaned_data = self.clean()
  File "/Users/chalfant/Desktop/site/COLOSite/requestApp/forms.py", line 39, in clean
    man_email= self.cleaned_data['man_email']
KeyError: 'man_email'
Exception while resolving variable 'request' in template '500.html'.
Traceback (most recent call last):
  File "/Library/Frameworks/Python.framework/Versions/3.6/lib/python3.6/site-packages/django/core/handlers/exception.py", line 41, in inner
    response = get_response(request)
  File "/Library/Frameworks/Python.framework/Versions/3.6/lib/python3.6/site-packages/django/core/handlers/base.py", line 187, in _get_response
    response = self.process_exception_by_middleware(e, request)
  File "/Library/Frameworks/Python.framework/Versions/3.6/lib/python3.6/site-packages/django/core/handlers/base.py", line 185, in _get_response
    response = wrapped_callback(request, *callback_args, **callback_kwargs)
  File "/Users/chalfant/Desktop/site/COLOSite/requestApp/views.py", line 19, in home
    if form.is_valid():
  File "/Library/Frameworks/Python.framework/Versions/3.6/lib/python3.6/site-packages/django/forms/forms.py", line 183, in is_valid
    return self.is_bound and not self.errors
  File "/Library/Frameworks/Python.framework/Versions/3.6/lib/python3.6/site-packages/django/forms/forms.py", line 175, in errors
    self.full_clean()
  File "/Library/Frameworks/Python.framework/Versions/3.6/lib/python3.6/site-packages/django/forms/forms.py", line 385, in full_clean
    self._clean_form()
  File "/Library/Frameworks/Python.framework/Versions/3.6/lib/python3.6/site-packages/django/forms/forms.py", line 412, in _clean_form
    cleaned_data = self.clean()
  File "/Users/chalfant/Desktop/site/COLOSite/requestApp/forms.py", line 39, in clean
    man_email= self.cleaned_data['man_email']
KeyError: 'man_email'

During handling of the above exception, another exception occurred:

Traceback (most recent call last):
  File "/Library/Frameworks/Python.framework/Versions/3.6/lib/python3.6/site-packages/django/template/base.py", line 882, in _resolve_lookup
    current = current[bit]
  File "/Library/Frameworks/Python.framework/Versions/3.6/lib/python3.6/site-packages/django/template/context.py", line 87, in __getitem__
    raise KeyError(key)
KeyError: 'request'

During handling of the above exception, another exception occurred:

Traceback (most recent call last):
  File "/Library/Frameworks/Python.framework/Versions/3.6/lib/python3.6/site-packages/django/template/base.py", line 888, in _resolve_lookup
    if isinstance(current, BaseContext) and getattr(type(current), bit):
AttributeError: type object 'Context' has no attribute 'request'

During handling of the above exception, another exception occurred:

Traceback (most recent call last):
  File "/Library/Frameworks/Python.framework/Versions/3.6/lib/python3.6/site-packages/django/template/base.py", line 896, in _resolve_lookup
    current = current[int(bit)]
ValueError: invalid literal for int() with base 10: 'request'

During handling of the above exception, another exception occurred:

Traceback (most recent call last):
  File "/Library/Frameworks/Python.framework/Versions/3.6/lib/python3.6/site-packages/django/template/base.py", line 903, in _resolve_lookup
    (bit, current))  # missing attribute
django.template.base.VariableDoesNotExist: Failed lookup for key [request] in "[{'True': True, 'False': False, 'None': None}]"
"POST / HTTP/1.1" 500 746
"GET /colo/ HTTP/1.1" 200 14410
Not Found: /colo/
"POST /colo/ HTTP/1.1" 404 745
Not Found: /colo/
"POST /colo/ HTTP/1.1" 404 745
Not Found: /colo/
"POST /colo/ HTTP/1.1" 404 745
Not Found: /colo/
"POST /colo/ HTTP/1.1" 404 745
"GET /colo/ HTTP/1.1" 200 14410
Not Found: /colo/
"POST /colo/ HTTP/1.1" 404 745
Not Found: /colo/
"POST /colo/ HTTP/1.1" 404 745
INFO "GET /colo/ HTTP/1.1" 200 14410
WARNING Not Found: /colo/
WARNING "POST /colo/ HTTP/1.1" 404 745
WARNING Not Found: /colo/
WARNING "POST /colo/ HTTP/1.1" 404 745
"GET /colo/ HTTP/1.1" 200 14410
Not Found: /colo/
"POST /colo/ HTTP/1.1" 404 745
Internal Server Error: /colo/
Traceback (most recent call last):
  File "/Library/Frameworks/Python.framework/Versions/3.6/lib/python3.6/site-packages/django/db/models/fields/__init__.py", line 2396, in to_python
    return uuid.UUID(value)
  File "/Library/Frameworks/Python.framework/Versions/3.6/lib/python3.6/uuid.py", line 140, in __init__
    raise ValueError('badly formed hexadecimal UUID string')
ValueError: badly formed hexadecimal UUID string

During handling of the above exception, another exception occurred:

Traceback (most recent call last):
  File "/Library/Frameworks/Python.framework/Versions/3.6/lib/python3.6/site-packages/django/core/handlers/exception.py", line 41, in inner
    response = get_response(request)
  File "/Library/Frameworks/Python.framework/Versions/3.6/lib/python3.6/site-packages/django/core/handlers/base.py", line 187, in _get_response
    response = self.process_exception_by_middleware(e, request)
  File "/Library/Frameworks/Python.framework/Versions/3.6/lib/python3.6/site-packages/django/core/handlers/base.py", line 185, in _get_response
    response = wrapped_callback(request, *callback_args, **callback_kwargs)
  File "/Users/chalfant/Desktop/site/COLOSite/requestApp/views.py", line 132, in COLO
    user= get_object_or_404(COLOUser, pk= uuid4).delete()
  File "/Library/Frameworks/Python.framework/Versions/3.6/lib/python3.6/site-packages/django/shortcuts.py", line 85, in get_object_or_404
    return queryset.get(*args, **kwargs)
  File "/Library/Frameworks/Python.framework/Versions/3.6/lib/python3.6/site-packages/django/db/models/query.py", line 374, in get
    num = len(clone)
  File "/Library/Frameworks/Python.framework/Versions/3.6/lib/python3.6/site-packages/django/db/models/query.py", line 232, in __len__
    self._fetch_all()
  File "/Library/Frameworks/Python.framework/Versions/3.6/lib/python3.6/site-packages/django/db/models/query.py", line 1118, in _fetch_all
    self._result_cache = list(self._iterable_class(self))
  File "/Library/Frameworks/Python.framework/Versions/3.6/lib/python3.6/site-packages/django/db/models/query.py", line 53, in __iter__
    results = compiler.execute_sql(chunked_fetch=self.chunked_fetch)
  File "/Library/Frameworks/Python.framework/Versions/3.6/lib/python3.6/site-packages/django/db/models/sql/compiler.py", line 863, in execute_sql
    sql, params = self.as_sql()
  File "/Library/Frameworks/Python.framework/Versions/3.6/lib/python3.6/site-packages/django/db/models/sql/compiler.py", line 420, in as_sql
    where, w_params = self.compile(self.where) if self.where is not None else ("", [])
  File "/Library/Frameworks/Python.framework/Versions/3.6/lib/python3.6/site-packages/django/db/models/sql/compiler.py", line 373, in compile
    sql, params = node.as_sql(self, self.connection)
  File "/Library/Frameworks/Python.framework/Versions/3.6/lib/python3.6/site-packages/django/db/models/sql/where.py", line 79, in as_sql
    sql, params = compiler.compile(child)
  File "/Library/Frameworks/Python.framework/Versions/3.6/lib/python3.6/site-packages/django/db/models/sql/compiler.py", line 373, in compile
    sql, params = node.as_sql(self, self.connection)
  File "/Library/Frameworks/Python.framework/Versions/3.6/lib/python3.6/site-packages/django/db/models/lookups.py", line 170, in as_sql
    rhs_sql, rhs_params = self.process_rhs(compiler, connection)
  File "/Library/Frameworks/Python.framework/Versions/3.6/lib/python3.6/site-packages/django/db/models/lookups.py", line 103, in process_rhs
    return self.get_db_prep_lookup(value, connection)
  File "/Library/Frameworks/Python.framework/Versions/3.6/lib/python3.6/site-packages/django/db/models/lookups.py", line 196, in get_db_prep_lookup
    [get_db_prep_value(value, connection, prepared=True)]
  File "/Library/Frameworks/Python.framework/Versions/3.6/lib/python3.6/site-packages/django/db/models/fields/__init__.py", line 2387, in get_db_prep_value
    value = self.to_python(value)
  File "/Library/Frameworks/Python.framework/Versions/3.6/lib/python3.6/site-packages/django/db/models/fields/__init__.py", line 2401, in to_python
    params={'value': value},
django.core.exceptions.ValidationError: ["'dsadsadsadsadsadsadsadsadsadsad3e56d' is not a valid UUID."]
Exception while resolving variable 'request' in template '500.html'.
Traceback (most recent call last):
  File "/Library/Frameworks/Python.framework/Versions/3.6/lib/python3.6/site-packages/django/db/models/fields/__init__.py", line 2396, in to_python
    return uuid.UUID(value)
  File "/Library/Frameworks/Python.framework/Versions/3.6/lib/python3.6/uuid.py", line 140, in __init__
    raise ValueError('badly formed hexadecimal UUID string')
ValueError: badly formed hexadecimal UUID string

During handling of the above exception, another exception occurred:

Traceback (most recent call last):
  File "/Library/Frameworks/Python.framework/Versions/3.6/lib/python3.6/site-packages/django/core/handlers/exception.py", line 41, in inner
    response = get_response(request)
  File "/Library/Frameworks/Python.framework/Versions/3.6/lib/python3.6/site-packages/django/core/handlers/base.py", line 187, in _get_response
    response = self.process_exception_by_middleware(e, request)
  File "/Library/Frameworks/Python.framework/Versions/3.6/lib/python3.6/site-packages/django/core/handlers/base.py", line 185, in _get_response
    response = wrapped_callback(request, *callback_args, **callback_kwargs)
  File "/Users/chalfant/Desktop/site/COLOSite/requestApp/views.py", line 132, in COLO
    user= get_object_or_404(COLOUser, pk= uuid4).delete()
  File "/Library/Frameworks/Python.framework/Versions/3.6/lib/python3.6/site-packages/django/shortcuts.py", line 85, in get_object_or_404
    return queryset.get(*args, **kwargs)
  File "/Library/Frameworks/Python.framework/Versions/3.6/lib/python3.6/site-packages/django/db/models/query.py", line 374, in get
    num = len(clone)
  File "/Library/Frameworks/Python.framework/Versions/3.6/lib/python3.6/site-packages/django/db/models/query.py", line 232, in __len__
    self._fetch_all()
  File "/Library/Frameworks/Python.framework/Versions/3.6/lib/python3.6/site-packages/django/db/models/query.py", line 1118, in _fetch_all
    self._result_cache = list(self._iterable_class(self))
  File "/Library/Frameworks/Python.framework/Versions/3.6/lib/python3.6/site-packages/django/db/models/query.py", line 53, in __iter__
    results = compiler.execute_sql(chunked_fetch=self.chunked_fetch)
  File "/Library/Frameworks/Python.framework/Versions/3.6/lib/python3.6/site-packages/django/db/models/sql/compiler.py", line 863, in execute_sql
    sql, params = self.as_sql()
  File "/Library/Frameworks/Python.framework/Versions/3.6/lib/python3.6/site-packages/django/db/models/sql/compiler.py", line 420, in as_sql
    where, w_params = self.compile(self.where) if self.where is not None else ("", [])
  File "/Library/Frameworks/Python.framework/Versions/3.6/lib/python3.6/site-packages/django/db/models/sql/compiler.py", line 373, in compile
    sql, params = node.as_sql(self, self.connection)
  File "/Library/Frameworks/Python.framework/Versions/3.6/lib/python3.6/site-packages/django/db/models/sql/where.py", line 79, in as_sql
    sql, params = compiler.compile(child)
  File "/Library/Frameworks/Python.framework/Versions/3.6/lib/python3.6/site-packages/django/db/models/sql/compiler.py", line 373, in compile
    sql, params = node.as_sql(self, self.connection)
  File "/Library/Frameworks/Python.framework/Versions/3.6/lib/python3.6/site-packages/django/db/models/lookups.py", line 170, in as_sql
    rhs_sql, rhs_params = self.process_rhs(compiler, connection)
  File "/Library/Frameworks/Python.framework/Versions/3.6/lib/python3.6/site-packages/django/db/models/lookups.py", line 103, in process_rhs
    return self.get_db_prep_lookup(value, connection)
  File "/Library/Frameworks/Python.framework/Versions/3.6/lib/python3.6/site-packages/django/db/models/lookups.py", line 196, in get_db_prep_lookup
    [get_db_prep_value(value, connection, prepared=True)]
  File "/Library/Frameworks/Python.framework/Versions/3.6/lib/python3.6/site-packages/django/db/models/fields/__init__.py", line 2387, in get_db_prep_value
    value = self.to_python(value)
  File "/Library/Frameworks/Python.framework/Versions/3.6/lib/python3.6/site-packages/django/db/models/fields/__init__.py", line 2401, in to_python
    params={'value': value},
django.core.exceptions.ValidationError: ["'dsadsadsadsadsadsadsadsadsadsad3e56d' is not a valid UUID."]

During handling of the above exception, another exception occurred:

Traceback (most recent call last):
  File "/Library/Frameworks/Python.framework/Versions/3.6/lib/python3.6/site-packages/django/template/base.py", line 882, in _resolve_lookup
    current = current[bit]
  File "/Library/Frameworks/Python.framework/Versions/3.6/lib/python3.6/site-packages/django/template/context.py", line 87, in __getitem__
    raise KeyError(key)
KeyError: 'request'

During handling of the above exception, another exception occurred:

Traceback (most recent call last):
  File "/Library/Frameworks/Python.framework/Versions/3.6/lib/python3.6/site-packages/django/template/base.py", line 888, in _resolve_lookup
    if isinstance(current, BaseContext) and getattr(type(current), bit):
AttributeError: type object 'Context' has no attribute 'request'

During handling of the above exception, another exception occurred:

Traceback (most recent call last):
  File "/Library/Frameworks/Python.framework/Versions/3.6/lib/python3.6/site-packages/django/template/base.py", line 896, in _resolve_lookup
    current = current[int(bit)]
ValueError: invalid literal for int() with base 10: 'request'

During handling of the above exception, another exception occurred:

Traceback (most recent call last):
  File "/Library/Frameworks/Python.framework/Versions/3.6/lib/python3.6/site-packages/django/template/base.py", line 903, in _resolve_lookup
    (bit, current))  # missing attribute
django.template.base.VariableDoesNotExist: Failed lookup for key [request] in "[{'True': True, 'False': False, 'None': None}]"
"POST /colo/ HTTP/1.1" 500 746
Exception while resolving variable 'request' in template '500.html'.
Traceback (most recent call last):
  File "/Library/Frameworks/Python.framework/Versions/3.6/lib/python3.6/site-packages/django/db/models/fields/__init__.py", line 2396, in to_python
    return uuid.UUID(value)
  File "/Library/Frameworks/Python.framework/Versions/3.6/lib/python3.6/uuid.py", line 140, in __init__
    raise ValueError('badly formed hexadecimal UUID string')
ValueError: badly formed hexadecimal UUID string

During handling of the above exception, another exception occurred:

Traceback (most recent call last):
  File "/Library/Frameworks/Python.framework/Versions/3.6/lib/python3.6/site-packages/django/core/handlers/exception.py", line 41, in inner
    response = get_response(request)
  File "/Library/Frameworks/Python.framework/Versions/3.6/lib/python3.6/site-packages/django/core/handlers/base.py", line 187, in _get_response
    response = self.process_exception_by_middleware(e, request)
  File "/Library/Frameworks/Python.framework/Versions/3.6/lib/python3.6/site-packages/django/core/handlers/base.py", line 185, in _get_response
    response = wrapped_callback(request, *callback_args, **callback_kwargs)
  File "/Users/chalfant/Desktop/site/COLOSite/requestApp/views.py", line 132, in COLO
    user= get_object_or_404(COLOUser, pk= uuid4).delete()
  File "/Library/Frameworks/Python.framework/Versions/3.6/lib/python3.6/site-packages/django/shortcuts.py", line 85, in get_object_or_404
    return queryset.get(*args, **kwargs)
  File "/Library/Frameworks/Python.framework/Versions/3.6/lib/python3.6/site-packages/django/db/models/query.py", line 374, in get
    num = len(clone)
  File "/Library/Frameworks/Python.framework/Versions/3.6/lib/python3.6/site-packages/django/db/models/query.py", line 232, in __len__
    self._fetch_all()
  File "/Library/Frameworks/Python.framework/Versions/3.6/lib/python3.6/site-packages/django/db/models/query.py", line 1118, in _fetch_all
    self._result_cache = list(self._iterable_class(self))
  File "/Library/Frameworks/Python.framework/Versions/3.6/lib/python3.6/site-packages/django/db/models/query.py", line 53, in __iter__
    results = compiler.execute_sql(chunked_fetch=self.chunked_fetch)
  File "/Library/Frameworks/Python.framework/Versions/3.6/lib/python3.6/site-packages/django/db/models/sql/compiler.py", line 863, in execute_sql
    sql, params = self.as_sql()
  File "/Library/Frameworks/Python.framework/Versions/3.6/lib/python3.6/site-packages/django/db/models/sql/compiler.py", line 420, in as_sql
    where, w_params = self.compile(self.where) if self.where is not None else ("", [])
  File "/Library/Frameworks/Python.framework/Versions/3.6/lib/python3.6/site-packages/django/db/models/sql/compiler.py", line 373, in compile
    sql, params = node.as_sql(self, self.connection)
  File "/Library/Frameworks/Python.framework/Versions/3.6/lib/python3.6/site-packages/django/db/models/sql/where.py", line 79, in as_sql
    sql, params = compiler.compile(child)
  File "/Library/Frameworks/Python.framework/Versions/3.6/lib/python3.6/site-packages/django/db/models/sql/compiler.py", line 373, in compile
    sql, params = node.as_sql(self, self.connection)
  File "/Library/Frameworks/Python.framework/Versions/3.6/lib/python3.6/site-packages/django/db/models/lookups.py", line 170, in as_sql
    rhs_sql, rhs_params = self.process_rhs(compiler, connection)
  File "/Library/Frameworks/Python.framework/Versions/3.6/lib/python3.6/site-packages/django/db/models/lookups.py", line 103, in process_rhs
    return self.get_db_prep_lookup(value, connection)
  File "/Library/Frameworks/Python.framework/Versions/3.6/lib/python3.6/site-packages/django/db/models/lookups.py", line 196, in get_db_prep_lookup
    [get_db_prep_value(value, connection, prepared=True)]
  File "/Library/Frameworks/Python.framework/Versions/3.6/lib/python3.6/site-packages/django/db/models/fields/__init__.py", line 2387, in get_db_prep_value
    value = self.to_python(value)
  File "/Library/Frameworks/Python.framework/Versions/3.6/lib/python3.6/site-packages/django/db/models/fields/__init__.py", line 2401, in to_python
    params={'value': value},
django.core.exceptions.ValidationError: ["'dsadsadsadsadsadsadsadsadsadsad3e56d' is not a valid UUID."]

During handling of the above exception, another exception occurred:

Traceback (most recent call last):
  File "/Library/Frameworks/Python.framework/Versions/3.6/lib/python3.6/site-packages/django/template/base.py", line 882, in _resolve_lookup
    current = current[bit]
  File "/Library/Frameworks/Python.framework/Versions/3.6/lib/python3.6/site-packages/django/template/context.py", line 87, in __getitem__
    raise KeyError(key)
KeyError: 'request'

During handling of the above exception, another exception occurred:

Traceback (most recent call last):
  File "/Library/Frameworks/Python.framework/Versions/3.6/lib/python3.6/site-packages/django/template/base.py", line 888, in _resolve_lookup
    if isinstance(current, BaseContext) and getattr(type(current), bit):
AttributeError: type object 'Context' has no attribute 'request'

During handling of the above exception, another exception occurred:

Traceback (most recent call last):
  File "/Library/Frameworks/Python.framework/Versions/3.6/lib/python3.6/site-packages/django/template/base.py", line 896, in _resolve_lookup
    current = current[int(bit)]
ValueError: invalid literal for int() with base 10: 'request'

During handling of the above exception, another exception occurred:

Traceback (most recent call last):
  File "/Library/Frameworks/Python.framework/Versions/3.6/lib/python3.6/site-packages/django/template/base.py", line 903, in _resolve_lookup
    (bit, current))  # missing attribute
django.template.base.VariableDoesNotExist: Failed lookup for key [request] in "[{'True': True, 'False': False, 'None': None}]"
"POST /colo/ HTTP/1.1" 500 746
Exception while resolving variable 'request' in template '500.html'.
Traceback (most recent call last):
  File "/Library/Frameworks/Python.framework/Versions/3.6/lib/python3.6/site-packages/django/db/models/fields/__init__.py", line 2396, in to_python
    return uuid.UUID(value)
  File "/Library/Frameworks/Python.framework/Versions/3.6/lib/python3.6/uuid.py", line 140, in __init__
    raise ValueError('badly formed hexadecimal UUID string')
ValueError: badly formed hexadecimal UUID string

During handling of the above exception, another exception occurred:

Traceback (most recent call last):
  File "/Library/Frameworks/Python.framework/Versions/3.6/lib/python3.6/site-packages/django/core/handlers/exception.py", line 41, in inner
    response = get_response(request)
  File "/Library/Frameworks/Python.framework/Versions/3.6/lib/python3.6/site-packages/django/core/handlers/base.py", line 187, in _get_response
    response = self.process_exception_by_middleware(e, request)
  File "/Library/Frameworks/Python.framework/Versions/3.6/lib/python3.6/site-packages/django/core/handlers/base.py", line 185, in _get_response
    response = wrapped_callback(request, *callback_args, **callback_kwargs)
  File "/Users/chalfant/Desktop/site/COLOSite/requestApp/views.py", line 132, in COLO
    user= get_object_or_404(COLOUser, pk= uuid4).delete()
  File "/Library/Frameworks/Python.framework/Versions/3.6/lib/python3.6/site-packages/django/shortcuts.py", line 85, in get_object_or_404
    return queryset.get(*args, **kwargs)
  File "/Library/Frameworks/Python.framework/Versions/3.6/lib/python3.6/site-packages/django/db/models/query.py", line 374, in get
    num = len(clone)
  File "/Library/Frameworks/Python.framework/Versions/3.6/lib/python3.6/site-packages/django/db/models/query.py", line 232, in __len__
    self._fetch_all()
  File "/Library/Frameworks/Python.framework/Versions/3.6/lib/python3.6/site-packages/django/db/models/query.py", line 1118, in _fetch_all
    self._result_cache = list(self._iterable_class(self))
  File "/Library/Frameworks/Python.framework/Versions/3.6/lib/python3.6/site-packages/django/db/models/query.py", line 53, in __iter__
    results = compiler.execute_sql(chunked_fetch=self.chunked_fetch)
  File "/Library/Frameworks/Python.framework/Versions/3.6/lib/python3.6/site-packages/django/db/models/sql/compiler.py", line 863, in execute_sql
    sql, params = self.as_sql()
  File "/Library/Frameworks/Python.framework/Versions/3.6/lib/python3.6/site-packages/django/db/models/sql/compiler.py", line 420, in as_sql
    where, w_params = self.compile(self.where) if self.where is not None else ("", [])
  File "/Library/Frameworks/Python.framework/Versions/3.6/lib/python3.6/site-packages/django/db/models/sql/compiler.py", line 373, in compile
    sql, params = node.as_sql(self, self.connection)
  File "/Library/Frameworks/Python.framework/Versions/3.6/lib/python3.6/site-packages/django/db/models/sql/where.py", line 79, in as_sql
    sql, params = compiler.compile(child)
  File "/Library/Frameworks/Python.framework/Versions/3.6/lib/python3.6/site-packages/django/db/models/sql/compiler.py", line 373, in compile
    sql, params = node.as_sql(self, self.connection)
  File "/Library/Frameworks/Python.framework/Versions/3.6/lib/python3.6/site-packages/django/db/models/lookups.py", line 170, in as_sql
    rhs_sql, rhs_params = self.process_rhs(compiler, connection)
  File "/Library/Frameworks/Python.framework/Versions/3.6/lib/python3.6/site-packages/django/db/models/lookups.py", line 103, in process_rhs
    return self.get_db_prep_lookup(value, connection)
  File "/Library/Frameworks/Python.framework/Versions/3.6/lib/python3.6/site-packages/django/db/models/lookups.py", line 196, in get_db_prep_lookup
    [get_db_prep_value(value, connection, prepared=True)]
  File "/Library/Frameworks/Python.framework/Versions/3.6/lib/python3.6/site-packages/django/db/models/fields/__init__.py", line 2387, in get_db_prep_value
    value = self.to_python(value)
  File "/Library/Frameworks/Python.framework/Versions/3.6/lib/python3.6/site-packages/django/db/models/fields/__init__.py", line 2401, in to_python
    params={'value': value},
django.core.exceptions.ValidationError: ["'dsadsadsadsadsadsadsadsadsadsad3e56d' is not a valid UUID."]

During handling of the above exception, another exception occurred:

Traceback (most recent call last):
  File "/Library/Frameworks/Python.framework/Versions/3.6/lib/python3.6/site-packages/django/template/base.py", line 882, in _resolve_lookup
    current = current[bit]
  File "/Library/Frameworks/Python.framework/Versions/3.6/lib/python3.6/site-packages/django/template/context.py", line 87, in __getitem__
    raise KeyError(key)
KeyError: 'request'

During handling of the above exception, another exception occurred:

Traceback (most recent call last):
  File "/Library/Frameworks/Python.framework/Versions/3.6/lib/python3.6/site-packages/django/template/base.py", line 888, in _resolve_lookup
    if isinstance(current, BaseContext) and getattr(type(current), bit):
AttributeError: type object 'Context' has no attribute 'request'

During handling of the above exception, another exception occurred:

Traceback (most recent call last):
  File "/Library/Frameworks/Python.framework/Versions/3.6/lib/python3.6/site-packages/django/template/base.py", line 896, in _resolve_lookup
    current = current[int(bit)]
ValueError: invalid literal for int() with base 10: 'request'

During handling of the above exception, another exception occurred:

Traceback (most recent call last):
  File "/Library/Frameworks/Python.framework/Versions/3.6/lib/python3.6/site-packages/django/template/base.py", line 903, in _resolve_lookup
    (bit, current))  # missing attribute
django.template.base.VariableDoesNotExist: Failed lookup for key [request] in "[{'True': True, 'False': False, 'None': None}]"
"POST /colo/ HTTP/1.1" 500 746
WARNING "POST /colo/ HTTP/1.1" 404 745 2017-08-10 11:12:15,179
INFO "GET /colo/ HTTP/1.1" 200 14410 2017-08-10 11:12:45,663
WARNING "POST /colo/ HTTP/1.1" 404 745 2017-08-10 11:13:30,044
WARNING "POST /colo/ HTTP/1.1" 404 745 2017-08-10 11:13:43,261
"POST /colo/ HTTP/1.1" 404 745
"POST /colo/ HTTP/1.1" 404 745
WARNING "POST /colo/ HTTP/1.1" 404 745 2017-08-10 11:16:00,022
WARNING "POST /colo/ HTTP/1.1" 404 745 2017-08-10 11:17:05,282
ERROR You're accessing the development server over HTTPS, but it only supports HTTP.
 2017-08-10 11:40:30,413
ERROR You're accessing the development server over HTTPS, but it only supports HTTP.
 2017-08-10 11:40:30,413
ERROR You're accessing the development server over HTTPS, but it only supports HTTP.
 2017-08-10 11:40:30,415
ERROR You're accessing the development server over HTTPS, but it only supports HTTP.
 2017-08-10 11:40:59,092
ERROR You're accessing the development server over HTTPS, but it only supports HTTP.
 2017-08-10 11:40:59,092
ERROR You're accessing the development server over HTTPS, but it only supports HTTP.
 2017-08-10 11:40:59,235
ERROR You're accessing the development server over HTTPS, but it only supports HTTP.
 2017-08-10 11:41:01,428
ERROR You're accessing the development server over HTTPS, but it only supports HTTP.
 2017-08-10 11:41:01,429
ERROR You're accessing the development server over HTTPS, but it only supports HTTP.
 2017-08-10 11:41:01,430
ERROR You're accessing the development server over HTTPS, but it only supports HTTP.
 2017-08-10 11:41:39,102
ERROR You're accessing the development server over HTTPS, but it only supports HTTP.
 2017-08-10 11:41:39,103
ERROR You're accessing the development server over HTTPS, but it only supports HTTP.
 2017-08-10 11:41:39,108
ERROR You're accessing the development server over HTTPS, but it only supports HTTP.
 2017-08-10 11:41:41,454
ERROR You're accessing the development server over HTTPS, but it only supports HTTP.
 2017-08-10 11:41:41,454
ERROR You're accessing the development server over HTTPS, but it only supports HTTP.
 2017-08-10 11:41:41,459
ERROR You're accessing the development server over HTTPS, but it only supports HTTP.
 2017-08-10 11:41:45,574
ERROR You're accessing the development server over HTTPS, but it only supports HTTP.
 2017-08-10 11:41:45,574
ERROR You're accessing the development server over HTTPS, but it only supports HTTP.
 2017-08-10 11:41:45,578
ERROR You're accessing the development server over HTTPS, but it only supports HTTP.
 2017-08-10 11:41:50,277
ERROR You're accessing the development server over HTTPS, but it only supports HTTP.
 2017-08-10 11:41:50,278
ERROR You're accessing the development server over HTTPS, but it only supports HTTP.
 2017-08-10 11:41:50,284
ERROR You're accessing the development server over HTTPS, but it only supports HTTP.
 2017-08-10 11:41:57,909
ERROR You're accessing the development server over HTTPS, but it only supports HTTP.
 2017-08-10 11:41:57,910
ERROR You're accessing the development server over HTTPS, but it only supports HTTP.
 2017-08-10 11:41:57,914
ERROR You're accessing the development server over HTTPS, but it only supports HTTP.
 2017-08-10 11:41:59,861
ERROR You're accessing the development server over HTTPS, but it only supports HTTP.
 2017-08-10 11:41:59,861
ERROR You're accessing the development server over HTTPS, but it only supports HTTP.
 2017-08-10 11:41:59,866
ERROR You're accessing the development server over HTTPS, but it only supports HTTP.
 2017-08-10 11:42:10,897
ERROR You're accessing the development server over HTTPS, but it only supports HTTP.
 2017-08-10 11:42:10,898
ERROR You're accessing the development server over HTTPS, but it only supports HTTP.
 2017-08-10 11:42:11,039
ERROR You're accessing the development server over HTTPS, but it only supports HTTP.
 2017-08-10 11:42:19,356
ERROR You're accessing the development server over HTTPS, but it only supports HTTP.
 2017-08-10 11:42:19,357
ERROR You're accessing the development server over HTTPS, but it only supports HTTP.
 2017-08-10 11:42:19,361
ERROR You're accessing the development server over HTTPS, but it only supports HTTP.
 2017-08-10 11:42:52,432
ERROR You're accessing the development server over HTTPS, but it only supports HTTP.
 2017-08-10 11:42:52,433
ERROR You're accessing the development server over HTTPS, but it only supports HTTP.
 2017-08-10 11:42:52,434
ERROR You're accessing the development server over HTTPS, but it only supports HTTP.
 2017-08-10 11:42:52,873
ERROR You're accessing the development server over HTTPS, but it only supports HTTP.
 2017-08-10 11:42:52,874
ERROR You're accessing the development server over HTTPS, but it only supports HTTP.
 2017-08-10 11:42:52,875
ERROR You're accessing the development server over HTTPS, but it only supports HTTP.
 2017-08-10 11:43:03,399
ERROR You're accessing the development server over HTTPS, but it only supports HTTP.
 2017-08-10 11:43:03,400
ERROR You're accessing the development server over HTTPS, but it only supports HTTP.
 2017-08-10 11:43:03,401
WARNING "GET /static/admin/css/dashboard.css HTTP/1.1" 404 770 2017-08-10 11:43:11,336
WARNING "GET /static/admin/css/base.css HTTP/1.1" 404 765 2017-08-10 11:43:11,337
ERROR You're accessing the development server over HTTPS, but it only supports HTTP.
 2017-08-10 11:43:16,562
ERROR You're accessing the development server over HTTPS, but it only supports HTTP.
 2017-08-10 11:43:16,562
ERROR You're accessing the development server over HTTPS, but it only supports HTTP.
 2017-08-10 11:43:16,563
ERROR You're accessing the development server over HTTPS, but it only supports HTTP.
 2017-08-10 11:43:22,548
ERROR You're accessing the development server over HTTPS, but it only supports HTTP.
 2017-08-10 11:43:22,549
ERROR You're accessing the development server over HTTPS, but it only supports HTTP.
 2017-08-10 11:43:22,693
WARNING "GET /static/requestApp/styles.css HTTP/1.1" 404 768 2017-08-10 11:43:29,816
WARNING "GET /static/requestApp/UCardSelected.png HTTP/1.1" 404 775 2017-08-10 11:43:29,816
WARNING "GET /static/requestApp/UCardSelected.png HTTP/1.1" 404 775 2017-08-10 11:43:39,018
WARNING "GET /static/requestApp/styles.css HTTP/1.1" 404 768 2017-08-10 11:43:39,018
WARNING "GET /static/requestApp/UCardSelected.png HTTP/1.1" 404 775 2017-08-10 11:43:39,936
WARNING "GET /static/requestApp/styles.css HTTP/1.1" 404 768 2017-08-10 11:43:39,936
WARNING "GET /static/requestApp/styles.css HTTP/1.1" 404 768 2017-08-10 11:43:40,637
WARNING "GET /static/requestApp/UCardSelected.png HTTP/1.1" 404 775 2017-08-10 11:43:40,637
WARNING "GET /static/requestApp/styles.css HTTP/1.1" 404 768 2017-08-10 11:43:41,084
WARNING "GET /static/requestApp/UCardSelected.png HTTP/1.1" 404 775 2017-08-10 11:43:41,085
WARNING "GET /static/requestApp/styles.css HTTP/1.1" 404 768 2017-08-10 11:43:41,524
WARNING "GET /static/requestApp/UCardSelected.png HTTP/1.1" 404 775 2017-08-10 11:43:41,524
WARNING "GET /static/requestApp/styles.css HTTP/1.1" 404 768 2017-08-10 11:43:41,998
WARNING "GET /static/requestApp/UCardSelected.png HTTP/1.1" 404 775 2017-08-10 11:43:41,998
WARNING "GET /static/requestApp/UCardSelected.png HTTP/1.1" 404 775 2017-08-10 11:43:52,438
WARNING "GET /static/requestApp/styles.css HTTP/1.1" 404 768 2017-08-10 11:43:52,438
WARNING "GET /static/requestApp/UCardSelected.png HTTP/1.1" 404 775 2017-08-10 11:44:18,871
WARNING "GET /static/requestApp/styles.css HTTP/1.1" 404 768 2017-08-10 11:44:18,871
WARNING "GET /static/requestApp/styles.css HTTP/1.1" 404 768 2017-08-10 11:44:19,942
WARNING "GET /static/requestApp/UCardSelected.png HTTP/1.1" 404 775 2017-08-10 11:44:19,942
WARNING "GET /static/requestApp/UCardSelected.png HTTP/1.1" 404 775 2017-08-10 11:44:20,912
WARNING "GET /static/requestApp/styles.css HTTP/1.1" 404 768 2017-08-10 11:44:20,912
WARNING "GET /static/requestApp/styles.css HTTP/1.1" 404 768 2017-08-10 11:44:21,835
WARNING "GET /static/requestApp/UCardSelected.png HTTP/1.1" 404 775 2017-08-10 11:44:21,835
WARNING "GET /static/requestApp/UCardSelected.png HTTP/1.1" 404 775 2017-08-10 11:44:22,394
WARNING "GET /static/requestApp/styles.css HTTP/1.1" 404 768 2017-08-10 11:44:22,394
WARNING "GET /static/requestApp/styles.css HTTP/1.1" 404 768 2017-08-10 11:44:22,581
WARNING "GET /static/requestApp/UCardSelected.png HTTP/1.1" 404 775 2017-08-10 11:44:22,582
WARNING "GET /static/requestApp/styles.css HTTP/1.1" 404 768 2017-08-10 11:44:22,917
WARNING "GET /static/requestApp/UCardSelected.png HTTP/1.1" 404 775 2017-08-10 11:44:22,918
WARNING "GET /static/requestApp/styles.css HTTP/1.1" 404 768 2017-08-10 11:44:23,081
WARNING "GET /static/requestApp/UCardSelected.png HTTP/1.1" 404 775 2017-08-10 11:44:23,081
WARNING "GET /static/requestApp/UCardSelected.png HTTP/1.1" 404 775 2017-08-10 11:44:23,402
WARNING "GET /static/requestApp/styles.css HTTP/1.1" 404 768 2017-08-10 11:44:23,402
WARNING "GET /static/requestApp/styles.css HTTP/1.1" 404 768 2017-08-10 11:44:23,721
WARNING "GET /static/requestApp/UCardSelected.png HTTP/1.1" 404 775 2017-08-10 11:44:23,721
WARNING "GET /static/requestApp/styles.css HTTP/1.1" 404 768 2017-08-10 11:44:23,877
WARNING "GET /static/requestApp/UCardSelected.png HTTP/1.1" 404 775 2017-08-10 11:44:23,878
WARNING "GET /static/requestApp/styles.css HTTP/1.1" 404 768 2017-08-10 11:44:24,190
WARNING "GET /static/requestApp/UCardSelected.png HTTP/1.1" 404 775 2017-08-10 11:44:24,191
WARNING "GET /static/requestApp/styles.css HTTP/1.1" 404 768 2017-08-10 11:44:24,353
WARNING "GET /static/requestApp/UCardSelected.png HTTP/1.1" 404 775 2017-08-10 11:44:24,354
WARNING "GET /static/requestApp/UCardSelected.png HTTP/1.1" 404 775 2017-08-10 11:44:24,688
WARNING "GET /static/requestApp/styles.css HTTP/1.1" 404 768 2017-08-10 11:44:24,688
WARNING "GET /static/admin/css/base.css HTTP/1.1" 404 765 2017-08-10 11:44:51,446
WARNING "GET /static/admin/css/dashboard.css HTTP/1.1" 404 770 2017-08-10 11:44:51,450
ERROR You're accessing the development server over HTTPS, but it only supports HTTP.
 2017-08-10 11:44:56,954
ERROR You're accessing the development server over HTTPS, but it only supports HTTP.
 2017-08-10 11:44:56,954
ERROR You're accessing the development server over HTTPS, but it only supports HTTP.
 2017-08-10 11:44:56,956
WARNING "GET /static/admin/css/base.css HTTP/1.1" 404 765 2017-08-10 11:45:31,065
WARNING "GET /static/admin/css/dashboard.css HTTP/1.1" 404 770 2017-08-10 11:45:31,069
WARNING "GET /favicon.ico HTTP/1.1" 404 751 2017-08-10 11:45:31,279
ERROR You're accessing the development server over HTTPS, but it only supports HTTP.
 2017-08-10 11:45:34,571
ERROR You're accessing the development server over HTTPS, but it only supports HTTP.
 2017-08-10 11:45:34,572
ERROR You're accessing the development server over HTTPS, but it only supports HTTP.
 2017-08-10 11:45:34,573
ERROR You're accessing the development server over HTTPS, but it only supports HTTP.
 2017-08-10 11:45:35,375
ERROR You're accessing the development server over HTTPS, but it only supports HTTP.
 2017-08-10 11:45:35,376
ERROR You're accessing the development server over HTTPS, but it only supports HTTP.
 2017-08-10 11:45:35,377
ERROR You're accessing the development server over HTTPS, but it only supports HTTP.
 2017-08-10 11:46:03,992
ERROR You're accessing the development server over HTTPS, but it only supports HTTP.
 2017-08-10 11:46:03,992
ERROR You're accessing the development server over HTTPS, but it only supports HTTP.
 2017-08-10 11:46:03,996
ERROR You're accessing the development server over HTTPS, but it only supports HTTP.
 2017-08-10 11:46:05,799
ERROR You're accessing the development server over HTTPS, but it only supports HTTP.
 2017-08-10 11:46:05,800
ERROR You're accessing the development server over HTTPS, but it only supports HTTP.
 2017-08-10 11:46:05,804
ERROR You're accessing the development server over HTTPS, but it only supports HTTP.
 2017-08-10 11:46:07,631
ERROR You're accessing the development server over HTTPS, but it only supports HTTP.
 2017-08-10 11:46:07,632
ERROR You're accessing the development server over HTTPS, but it only supports HTTP.
 2017-08-10 11:46:07,636
WARNING "GET /static/requestApp/styles.css HTTP/1.1" 404 768 2017-08-10 11:47:12,610
WARNING "GET /static/requestApp/UCardSelected.png HTTP/1.1" 404 775 2017-08-10 11:47:12,642
WARNING "GET /favicon.ico HTTP/1.1" 404 2993 2017-08-10 11:47:42,806
ERROR You're accessing the development server over HTTPS, but it only supports HTTP.
 2017-08-10 11:47:45,507
ERROR You're accessing the development server over HTTPS, but it only supports HTTP.
 2017-08-10 11:47:45,507
ERROR You're accessing the development server over HTTPS, but it only supports HTTP.
 2017-08-10 11:47:45,512
ERROR You're accessing the development server over HTTPS, but it only supports HTTP.
 2017-08-10 11:47:48,526
ERROR You're accessing the development server over HTTPS, but it only supports HTTP.
 2017-08-10 11:47:48,527
ERROR You're accessing the development server over HTTPS, but it only supports HTTP.
 2017-08-10 11:47:48,669
ERROR You're accessing the development server over HTTPS, but it only supports HTTP.
 2017-08-10 11:49:02,898
ERROR "POST / HTTP/1.1" 500 66128 2017-08-10 11:53:00,959
WARNING "GET / HTTP/1.1" 404 2948 2017-08-16 09:32:15,140
WARNING "GET /favicon.ico HTTP/1.1" 404 2999 2017-08-16 09:32:15,238
WARNING "GET / HTTP/1.1" 404 2948 2017-08-16 11:24:24,259
WARNING "GET /favicon.ico HTTP/1.1" 404 2999 2017-08-16 11:24:24,275
WARNING "GET /employee_confirm HTTP/1.1" 404 3014 2017-08-16 11:36:33,835
WARNING "GET / HTTP/1.1" 404 2948 2017-08-16 15:26:03,240
WARNING "GET /lsldc HTTP/1.1" 404 2981 2017-08-16 15:26:08,350
WARNING "GET /lsldc/ HTTP/1.1" 404 2984 2017-08-16 15:26:11,866
WARNING "GET /LSLDC/ HTTP/1.1" 404 2984 2017-08-16 15:27:24,383
WARNING "GET /LSLDC/ HTTP/1.1" 404 2984 2017-08-16 15:27:25,552
WARNING Forbidden (CSRF token missing or incorrect.): /manager_confirm/4on-a39e3c1e4f90d650e403/f4439db2-aef2-4748-a1f1-8ec674f38e6d 2017-08-16 16:13:25,248
WARNING "POST /manager_confirm/4on-a39e3c1e4f90d650e403/f4439db2-aef2-4748-a1f1-8ec674f38e6d HTTP/1.1" 403 2502 2017-08-16 16:13:25,259
WARNING "POST /manager_confirm/4on-a39e3c1e4f90d650e403/f4439db2-aef2-4748-a1f1-8ec674f38e6d HTTP/1.1" 404 1861 2017-08-16 16:15:08,900
WARNING "GET /manager_confirm/4on-a39e3c1e4f90d650e403/f4439db2-aef2-4748-a1f1-8ec674f38e6d HTTP/1.1" 404 1860 2017-08-16 16:15:43,129
ERROR "POST /manager_confirm/4on-511040e090915d32f5ab/e6560c1c-09fd-4553-a48d-bbe6f468e15e HTTP/1.1" 500 85435 2017-08-16 16:21:13,354
WARNING "POST /manager_confirm/4on-511040e090915d32f5ab/e6560c1c-09fd-4553-a48d-bbe6f468e15e HTTP/1.1" 404 1861 2017-08-16 16:21:33,689
